Workbook

Sheet Resumo
A1: Mapa de envolvidos: situação jurídica por estágio
A2: Pesquisa em fontes públicas, atualizada em 21/10/2026 (revisão 3, com o acervo a verdade.). Estágio ≠ culpa: só os "Condenado" têm decisão condenatória.
A4: Estágio | B4: Pessoas | C4: Quem
A5: Condenado | B5: =COUNTIF(Perfis!$H$2:$H$35,A5) | C5: Jair Messias Bolsonaro; Alexandre Ramagem; Augusto Heleno
A6: Preso, sem condenação | B6: =COUNTIF(Perfis!$H$2:$H$35,A6) | C6: Antônio Carlos Camilo Antunes; Alexandre Caetano dos Reis; Daniel Vorcaro; Fabiano Campos Zettel
A7: Investigado / alvo (sem denúncia) | B7: =COUNTIF(Perfis!$H$2:$H$35,A7) | C7: Fábio Luís Lula da Silva; Roberta Moreira Luchsinger; Willer Tomaz; Flávio Bolsonaro; Carlos Bolsonaro; Frederick Wassef; Ciro Nogueira; Mario Frias
A8: Citado, sem acusação | B8: =COUNTIF(Perfis!$H$2:$H$35,A8) | C8: Letícia Caetano dos Reis; Lídia Maria Figueiredo Mazelli; Renan Calheiros; Fabrício José Carlos de Queiroz; Richarlison; Kassio Nunes Marques; Kevin Marques; Sergio Fernando Moro; André Mendonça; Fábio Faria; Alfredo Gaspar
A9: Não pesquisado | B9: =COUNTIF(Perfis!$H$2:$H$35,A9) | C9: Mulher e filhas de Flávio; advogadas de Flávio; diretor jurídico; promoter; mordomo; mulheres das festas; eletricista; Antônio Marcos da Silva (sem fonte pública confirmada)
A10: Total | B10: =SUM(B5:B9)
A28: Notas de método
A29: • Pessoas privadas, menores e não nomeadas (família de Flávio, mulheres das festas, promoter, mordomo, eletricista, advogadas, diretor jurídico) não foram pesquisadas.
A30: • Localização é só cidade/UF noticiada, sem endereço residencial. Vivo/morto reflete as notícias mais recentes que achei; não encontrei registro de morte de ninguém.
A31: • "Milícia": só aparece vínculo apurado no caso Queiroz (transferências de Adriano da Nóbrega). Nenhuma fonte acusa Queiroz de integrar milícia.
A32: • Vários detalhes de 2026 vêm de manchetes ou de reportagens sem confirmação cruzada; marquei como "não confirmado" onde não consegui abrir a fonte.
A33: • Contexto eleitoral (revisão 2): 1º turno em 04/10/2026; Flávio (47,03%) e Lula (45,16%) vão ao 2º turno em 25/10. Moro foi eleito governador do PR e Carlos, senador por SC; Renan perdeu a reeleição.
A34: • Abas Nodes, Edges e Notes originais ficaram intactas.

Sheet Perfis
A1: Id | B1: Nome | C1: Grupo | D1: Quem é / histórico | E1: Onde atua ou vive (nível cidade/UF) | F1: Vivo ou morto | G1: Situação jurídica | H1: Estágio | I1: Milícia? | J1: Divergências com a planilha / ressalvas | K1: Fontes | L1: Checado em | M1: Mudou nesta revisão | N1: Foto (arquivo) | O1: Crédito da foto | P1: Link da fonte da foto
A2: careca | B2: Antônio Carlos Camilo Antunes ("Careca do INSS") | C2: Esquema do INSS | D2: Lobista. Declara-se gerente (renda declarada ~R$ 24,5 mil/mês), mas relatório o aponta como sócio de 22 empresas; pessoas e empresas ligadas a ele receberam ~R$ 53,6 mi. PF diz que mantinha offshore nas Ilhas Virgens Britânicas. Tinha 61 anos em jan/2026. O filho, Romeu, preso em dez/2025, foi solto por Mendonça em 09/09/2026 (tornozeleira, passaporte apreendido, sem sair de Brasília). | E2: Complexo da Papuda, Brasília (DF), ala de vulneráveis (Bloco V) desde jan/2026 | F2: Vivo (preso; confirmado em 09/09/2026) | G2: Preso desde 12/09/2025 (STF; Operação Sem Desconto; relator Mendonça), hoje na Papuda. Em jan/2026 Mendonça negou pedido de liberdade (decisão sigilosa), vendo risco de reiteração e de atrapalhar a investigação. Segue preso em set/2026. Em 2026 preparava uma proposta de delação, sem notícia de aceite. Nas fontes não há condenação nem denúncia. | H2: Preso, sem condenação | I2: Nada nas fontes. | J2: — | K2: CNN Brasil 12/09/2025 https://www.cnnbrasil.com.br/politica/quem-e-o-careca-do-inss-preso-em-operacao-da-pf-nesta-sexta-12/ | Delação (fev/2026) https://portaldeprefeitura.com.br/bastidores-da-politica/policia-federal/careca-do-inss-prepara-proposta-de-delacao-premiada-lulinha/615241/ | Gazeta do Povo https://www.gazetadopovo.com.br/republica/mendonca-mantem-prisao-preventiva-do-careca-do-inss/ | Rondônia ao Vivo 09/09/2026 https://www.rondoniaovivo.com/noticia/geral/2026/09/09/stf-mendonca-manda-soltar-filho-do-careca-do-inss.html | Metrópoles https://www.metropoles.com/colunas/manoela-alcantara/careca-do-inss-e-transferido-para-ala-de-vulneraveis-da-papuda | Revogação da prisão do filho do Careca do INSS (iclnoticias.com.br) https://iclnoticias.com.br/andre-mendonca-revoga-prisao-do-filho-do-careca/ | Endereço e contabilidade compartilhados em Brasília (iclnoticias.com.br) https://iclnoticias.com.br/empresas-de-flavio-bolsonaro-e-careca-do-inss/ | L2: 20/10/2026 | M2: Confirmado preso em 09/09/2026; local, idade e decisão de jan/2026 adicionados. 21/10/2026: importado do acervo a verdade. (bolsomaster.site). | N2: careca.jpg | O2: Edilson Rodrigues/Agência Senado · CC BY-SA 4.0 | P2: https://commons.wikimedia.org/wiki/File:CPMI_-_INSS_-_Comissão_Parlamentar_Mista_de_Inquérito_do_INSS_-_2025_(54811232041)_(cropped).jpg
A3: contador | B3: Alexandre Caetano dos Reis | C3: Esquema do INSS | D3: Contador, dono da Voga Serviços Contábeis; cuida também da contabilidade do escritório de advocacia de Flávio. Segundo reportagem, era sócio do Careca em offshore nas Ilhas Virgens Britânicas. | E3: Brasília/Águas Claras (DF) – escritório; hoje preso (Papuda, segundo Bahia Notícias) | F3: Vivo (preso) | G3: Preso em dez/2025 em desdobramento do caso INSS. Willer Tomaz tem procuração nos autos para defendê-lo. Sem condenação nas fontes. | H3: Preso, sem condenação | I3: Nada nas fontes. | J3: — | K3: Bahia Notícias https://www.bahianoticias.com.br/noticia/321055-empresas-de-flavio-bolsonaro-e-careca-do-inss-dividem-a-mesma-sala-e-possuem-o-mesmo-contador | Endereço e contabilidade compartilhados em Brasília (iclnoticias.com.br) https://iclnoticias.com.br/empresas-de-flavio-bolsonaro-e-careca-do-inss/ | L3: 20/10/2026 | M3: 21/10/2026: importado do acervo a verdade. (bolsomaster.site).
A4: leticia | B4: Letícia Caetano dos Reis | C4: Esquema do INSS | D4: Irmã do contador; administra o escritório de advocacia de Flávio desde 2021. Em entrevista à Agência Pública (2022) disse que chegou ao escritório por indicação de Willer Tomaz. | E4: Brasília/Águas Claras (DF) – local do escritório | F4: Vivo (sem registro de morte) | G4: Sem prisão, acusação ou investigação formal noticiada nas fontes que li. Aparece pelo vínculo familiar e profissional. | H4: Citado, sem acusação | I4: Nada nas fontes. | J4: Pessoa privada: mantive só o papel público no caso. | K4: Bahia Notícias (link acima) | L4: 20/10/2026 | M4: —
A5: lulinha | B5: Fábio Luís Lula da Silva ("Lulinha") | C5: Esquema do INSS | D5: Empresário, filho do presidente Lula. A PF informou ao STF que apura citações a ele no inquérito do INSS (relator Mendonça); uma hipótese é que fosse sócio oculto do Careca (mensagem citando "o filho do rapaz"). Em jan/2026 Mendonça autorizou a quebra do sigilo bancário dele e de Roberta; em 04/03/2026 Dino suspendeu a quebra de sigilo fiscal pedida pela CPMI. | E5: Não confirmado nas fontes | F5: Vivo | G5: Nega ser investigado. Em 17/10/2026 Roberta Luchsinger disse à CNN que pretende fazer delação e citou Lula e Lulinha; a defesa dele (advogado Guilherme Suguimori Santos) chamou as falas de "insinuações", disse que ele pôs sigilos à disposição da Justiça e que não foi indiciado na operação do INSS. Sem indiciamento, denúncia ou condenação. | H5: Investigado / alvo (sem denúncia) | I5: Nada nas fontes. | J5: Planilha diz "3 inquéritos no STF"; nas fontes que li aparece 1 inquérito (INSS) com citações a ele. Vale revisar esse número. | K5: Brasil Agro https://brasilagro.com.br/conteudo/pf-apura-se-lulinha-foi-socio-oculto-de-careca-do-inss.html | Poder360 https://www.poder360.com.br/poder-justica/amiga-de-lulinha-nega-ter-repassado-valores-do-careca-do-inss-a-pf/ | Gazeta do Povo 17/10/2026 https://www.gazetadopovo.com.br/republica/defesa-de-lulinha-nega-irregularidades-apos-declaracoes-de-lobista-roberta-luchsinger/ | L5: 20/10/2026 | M5: Adicionadas as falas de Roberta (17/10/2026) e a resposta da defesa.
A6: roberta | B6: Roberta Moreira Luchsinger | C6: Esquema do INSS | D6: Lobista/consultora (RL Consultoria e Intermediações), amiga de Lulinha. PF diz que ela recebeu cerca de R$ 1,5 mi em parcelas do Careca via a Brasília Consultoria Empresarial, que a PF chama de empresa de fachada. Defesa: tratativas de um projeto de canabidiol, sem relação com o INSS. Depôs à PF em 20/05/2026 negando ter repassado valores a Lulinha. | E6: São Paulo (SP) – alvo de busca em Higienópolis em dez/2025 | F6: Viva | G6: Segundo a Gazeta do Povo (17/10/2026), é investigada pela PF por suspeita de tráfico de influência envolvendo integrantes do governo federal. Em entrevista à CNN no mesmo dia disse que pretende fazer delação premiada e "não vai poupar ninguém", citando Lula e Lulinha; nenhum acordo firmado nas fontes. Sem denúncia ou condenação. | H6: Investigado / alvo (sem denúncia) | I6: Nada nas fontes. | J6: Planilha diz "~R$ 1 mi"; a PF fala em ordem de R$ 300 mil e ~R$ 1,5 mi no total. | K6: Poder360 (link acima) | Brasil Agro (link acima) | Gazeta do Povo (link na linha do Lulinha) | L6: 20/10/2026 | M6: Agora investigada por tráfico de influência e anuncia delação (17/10/2026).
A7: willer | B7: Willer Tomaz | C7: Willer Tomaz e sua rede | D7: Advogado em Brasília. Preso em 2017 sob suspeita de tentar interferir na Operação Greenfield (fundos de pensão). Alvo de busca em ago/2026 na Operação Sem Desconto (caso ligado ao senador Weverton Rocha). O inquérito sobre ele e Flávio (suposta lavagem via bets, Rede Loto) chegou ao STF em 08/10/2026 (relator Moraes) e foi revelado em 18–19/10. A PF diz que uma conta dele movimentou ~R$ 130 mi entre mar e mai/2025. Dono de empresas como WT, Alcazar e Cathedral. | E7: Brasília (DF) | F7: Vivo | G7: Investigado; nega irregularidades e fala em "pescaria probatória". Nas fontes não há denúncia nem condenação. | H7: Investigado / alvo (sem denúncia) | I7: Nada nas fontes. | J7: — | K7: A Tarde https://atarde.com.br/eleicoes/quem-e-willer-tomaz-advogado-suspeito-de-ligacao-com-flavio-bolsonaro-1406358 | Tribuna do Sertão 19/10/2026 https://www.tribunadosertao.com.br/poder-e-governo/2026/10/19/1000284-flavio-bolsonaro-e-investigado-pela-pf-por-suspeita-de-lavagem-de-dinheiro-com-advogado-willer-tomaz | CartaCapital 18/10/2026 https://www.cartacapital.com.br/politica/flavio-bolsonaro-e-alvo-de-segundo-inquerito-no-stf-por-suspeita-de-lavagem-de-dinheiro/ | CNN Brasil https://www.cnnbrasil.com.br/politica/advogado-amigo-de-flavio-movimentou-r-130-milhoes-em-tres-meses-diz-pf/ | O voo no jato de Vorcaro em janeiro de 2025 (piaui.uol.com.br) https://piaui.uol.com.br/web/flavio-bolsonaro-viajou-em-jato-de-vorcaro/ | E-mails sobre vínculo bancário com Willer Tomaz (noticias.uol.com.br) https://noticias.uol.com.br/colunas/fabio-serapiao/2026/10/10/flavio-dividia-conta-com-suspeito-de-lavar-dinheiro-do-inss-indicam-emails.htm | A disputa pelo imóvel comprado por Richarlison (iclnoticias.com.br) https://iclnoticias.com.br/advogado-defendia-amigo-de-flavio-bolsonaro/ | A disputa pelo imóvel comprado por Richarlison (iclnoticias.com.br) https://iclnoticias.com.br/pf-e-acionada-flavio-bolsonaro-richarlisson/ | L7: 20/10/2026 | M7: Data de entrada no STF (08/10/2026), valores e confirmação da busca de ago/2026. 21/10/2026: importado do acervo a verdade. (bolsomaster.site). | N7: willer.jpg | O7: Agência Senado · CC BY 2.0 | P7: https://commons.wikimedia.org/wiki/File:Willer_Tomaz_de_Souza.jpg
A8: lidia | B8: Lídia Maria Figueiredo Mazelli | C8: Willer Tomaz e sua rede | D8: 61 anos. Dirigente formal de 14 empresas ligadas a Willer (WT, Jet Line, Friponor, RioPag, Ícaro Aviation etc.); assinou a escritura da mansão de Angra. Teve vínculo formal com o escritório de Willer entre mar/2019 e set/2020. Ao ser abordada disse ser doméstica; depois afirmou nunca ter sido empregada doméstica e que respondeu assim por medo. A defesa de Willer diz que é administradora de empresas. | E8: Não informado | F8: Viva | G8: A reportagem não a acusa nem a apresenta como investigada; ela diz não ser investigada. Suspeitas recaem sobre Willer e as empresas (ex.: Loterj acusa a RioPag de não repassar R$ 20,9 mi ao estado). | H8: Citado, sem acusação | I8: Nada nas fontes. | J8: Planilha diz "diz ser doméstica": ela depois desmentiu isso. Hipótese de "laranja" é da reportagem, não está comprovada. | K8: ICL Notícias https://iclnoticias.com.br/domestica-preside-empresas-fraude-flavio/ | L8: 20/10/2026 | M8: —
A9: renan | B9: Renan Calheiros | C9: Willer Tomaz e sua rede | D9: Senador (MDB-AL), relator da CPI da Pandemia. Perdeu a reeleição em 04/10/2026 e deixará o Senado após 32 anos (mandato vai até jan/2027). Inquérito sobre favorecimento à Hypermarcas foi arquivado por Fachin em out/2024; Dino mandou a PF concluir em 90 dias outro inquérito (Postalis, lobista Milton Lyra), sem data na fonte. | E9: Alagoas (AL) | F9: Vivo | G9: Sem condenação nas fontes; inquérito Postalis com status não confirmado. Resultado eleitoral baseado nos títulos de Poder360 e O Tempo (o corpo da matéria não abriu). | H9: Citado, sem acusação | I9: Nada nas fontes. | J9: Não achei notícia de 2026 sobre os inquéritos; só sobre a eleição. | K9: Portal de Prefeitura (Fachin) https://portaldeprefeitura.com.br/bastidores-da-politica/fachin-arquiva-investigacao-contra-renan-calheiros-e-eduardo-braga-por/582759/ | Poder360 https://www.poder360.com.br/poder-eleicoes-2026/renan-calheiros-perde-eleicao-e-deixara-o-senado-apos-32-anos/ | O Tempo https://www.otempo.com.br/eleicoes/2026/2026/10/4/renan-calheiros-perde-eleicao-e-deixara-senado-apos-32-anos | L9: 20/10/2026 | M9: Perdeu a reeleição em 04/10/2026. | N9: renan.jpg | O9: Agência Senado · uso livre | P9: https://commons.wikimedia.org/wiki/File:Senador_Renan_Calheiros_MDB_-_AL.jpg
A10: flavio | B10: Flávio Bolsonaro | C10: Flávio e família | D10: Nascido em 30/04/1981, Resende (RJ). Advogado e empresário; deputado estadual desde 2003, senador pelo RJ desde 2019. Candidato do PL à Presidência: no 1º turno (04/10/2026) teve 47,03% dos votos válidos contra 45,16% de Lula; o 2º turno é em 25/10/2026. Rachadinha: denunciado pelo MPRJ em out/2020 com Queiroz e outros 15; provas anuladas pelo STJ/STF em nov/2021; denúncia rejeitada e caso arquivado em 2022. Hoje há dois inquéritos no STF: (1) Dark Horse, autorizado por Mendonça em 23/07/2026 (~US$ 24 mi negociados; Coaf/piauí apontam ~US$ 12,3 mi repassados por Vorcaro ao fundo Havengate); em 10/09 a PF fez a Operação Make Up (49 mandados; alvos incluem a produtora Karina Gama e o deputado Mário Frias). (2) lavagem com Willer Tomaz, chegou ao STF em 08/10/2026 (relator Moraes). Em 12/10 Moraes liberou as visitas dele ao pai, suspensas desde julho por ele ter publicado uma carta de Jair. | E10: RJ (base eleitoral); mandato em Brasília | F10: Vivo | G10: Nega: chama o 2º inquérito de politicamente motivado e a relação com Willer de amizade entre famílias; diz que o filme foi patrocínio. Sem denúncia nova nem condenação. | H10: Investigado / alvo (sem denúncia) | I10: Sem acusação de milícia. Mãe e ex-esposa de Adriano da Nóbrega (miliciano) constavam como funcionárias do gabinete dele; Flávio atribuiu as contratações a Queiroz. | J10: Acervo a verdade.: Aos Fatos contou ao menos 43 declarações falsas dele sobre a relação com Vorcaro. Os números do celular variam por fonte (Piauí: 11 meses e 110 registros; Estadão: 3 meses e 6 encontros) e não devem ser somados. Os R$ 134 mi negociados e ≥ R$ 61 mi repassados foram para o filme, o que não comprova recebimento pessoal. | K10: Wikipedia pt https://pt.wikipedia.org/wiki/Fl%C3%A1vio_Bolsonaro | Tribuna do Sertão (link acima) | O Povo 23/07/2026 https://www.opovo.com.br/noticias/politica/2026/07/23/amp/andre-mendonca-autoriza-inquerito-sobre-repasses-para-dark-horse-filme-sobre-jair-bolsonaro.html | Resultado do 1º turno https://portaldeprefeitura.com.br/bastidores-da-politica/eleicoes-2026-com-100-das-secoes-totalizadas-flavio-tem-4703-e/633498/ | Wikipedia (Banco Master scandal) https://en.wikipedia.org/wiki/Banco_Master_scandal | JB 12/10/2026 https://www.jb.com.br/brasil/justica/2026/10/1061206-moraes-autoriza-flavio-bolsonaro-a-visitar-jair-bolsonaro-em-prisao-domiciliar.html | A investigação sobre o financiamento de Dark Horse (bbc.com) https://www.bbc.com/portuguese/articles/c4g5ky0r25jo | A investigação sobre o financiamento de Dark Horse (em.com.br) https://www.em.com.br/politica/2026/09/7498387-flavio-bolsonaro-vira-investigado-do-dark-horse-que-segue-sob-sigilo.html | O acordo de R$ 134 milhões para o filme (intercept.com.br) https://www.intercept.com.br/2026/05/13/audio-flavio-negociou-vorcaro-milhoes/ | A checagem de declarações sobre Vorcaro (aosfatos.org) https://www.aosfatos.org/noticias/flavio-mentiu-ao-menos-43-vezes-sobre-envolvimento-com-vorcaro/ | Os registros de contato no celular do banqueiro (piaui.uol.com.br) https://piaui.uol.com.br/web/mensagens-celular-flavio-vorcaro/ | As menções a encontros presenciais (estadao.com.br) https://www.estadao.com.br/politica/celular-de-vorcaro-tinha-tres-meses-de-conversa-com-flavio-bolsonaro-e-mencao-a-seis-encontros/ | O voo no jato de Vorcaro em janeiro de 2025 (piaui.uol.com.br) https://piaui.uol.com.br/web/flavio-bolsonaro-viajou-em-jato-de-vorcaro/ | O apartamento de Fabiano Zettel e Willer Tomaz (piaui.uol.com.br) https://piaui.uol.com.br/web/flavio-bolsonaro-zettel-tomaz-imovel-vila-nova-conceicao-sao-paulo/ | O aniversário em uma mansão gerida por empresa de Vorcaro (iclnoticias.com.br) https://iclnoticias.com.br/flavio-bolsonaro-aniversario-da-filha-em-mansao/ | E-mails sobre vínculo bancário com Willer Tomaz (noticias.uol.com.br) https://noticias.uol.com.br/colunas/fabio-serapiao/2026/10/10/flavio-dividia-conta-com-suspeito-de-lavar-dinheiro-do-inss-indicam-emails.htm | Endereço e contabilidade compartilhados em Brasília (iclnoticias.com.br) https://iclnoticias.com.br/empresas-de-flavio-bolsonaro-e-careca-do-inss/ | Cargo na Câmara, faculdade e estágio no Rio (bbc.com) https://www.bbc.com/portuguese/brasil-46828487 | A acusação de rachadinhas na Alerj (valor.globo.com) https://valor.globo.com/politica/eleicoes-2026/noticia/2026/09/01/flavio-bolsonaro-relembre-o-processo-da-rachadinha.ghtml | A acusação de rachadinhas na Alerj (folhadelondrina.com.br) https://www.folhadelondrina.com.br/ultimas-noticias/entenda-quais-provas-da-rachadinha-contra-flavio-bolsonaro-ainda-valem-3131387e.html | A investigação da loja Kopenhagen (oglobo.globo.com) https://oglobo.globo.com/politica/alvo-de-investigacao-das-rachadinhas-loja-de-flavio-bolsonaro-no-rio-vendida-1-24867874 | Imóveis comprados pela família e investigações (g1.globo.com) https://g1.globo.com/jornal-nacional/noticia/2022/08/31/reportagem-do-uol-revela-que-51-imoveis-comprados-pela-familia-bolsonaro-foram-pagos-em-dinheiro-vivo.ghtml | Imóveis comprados pela família e investigações (noticias.uol.com.br) https://noticias.uol.com.br/politica/ultimas-noticias/2022/08/30/imoveis-cla-bolsonaro-objeto-de-investigacao-suspeita-dinheiro-vivo.htm | Imóveis comprados pela família e investigações (estadao.com.br) https://www.estadao.com.br/politica/investigacao-sobre-flaviobolsonaro-alcanca-37-imoveis/ | A compra e a quitação da mansão em Brasília (oglobo.globo.com) https://oglobo.globo.com/politica/eleicoes-2026/noticia/2026/08/14/video-mansao-que-fez-patrimonio-de-flavio-disparar-fica-em-terreno-de-2400-m-e-foi-quitada-27-anos-antes-do-previsto.ghtml | A análise do MPF sobre 37 transações imobiliárias (cnnbrasil.com.br) https://www.cnnbrasil.com.br/politica/o-mpf-ve-fortes-indicios-de-lavagem-de-dinheiro-em-bens-de-flavio-bolsonaro/a | A acusação do MP-RJ sobre organização criminosa (g1.globo.com) https://g1.globo.com/rj/rio-de-janeiro/noticia/2019/12/19/mp-do-rj-detalha-suposto-esquema-de-corrupcao-envolvendo-entao-deputado-flavio-bolsonaro.ghtml?utm_source=twitter&utm_medium=social&utm_campaign=g1 | Destinação de emendas e entidades questionadas (revistaforum.com.br) https://revistaforum.com.br/politica/flavio-bolsonaro-emendas-ong-fantasma-e-instituto-de-miliciano/ | L10: 20/10/2026 | M10: Resultado do 1º turno; 2º inquérito no STF; Operação Make Up; visitas ao pai liberadas. 21/10/2026: importado do acervo a verdade. (bolsomaster.site). | N10: flavio.jpg | O10: Agência Senado · uso livre | P10: https://commons.wikimedia.org/wiki/File:Foto_oficial_do_senador_Flávio_Bolsonaro_(v._AgSen)_(3x4).jpg
A11: fam | B11: Mulher e filhas de Flávio | C11: Flávio e família | D11: Não pesquisei. Inclui menores de idade e aparecem na planilha só como passageiras do jato em jan/2025. | E11: — | F11: — | G11: — | H11: Não pesquisado | I11: — | J11: Decisão deliberada: sem papel público no caso. | K11: — | L11: 20/10/2026 | M11: —
A12: carlos | B12: Carlos Bolsonaro | C12: Flávio e família | D12: Nascido em 07/12/1982, Resende (RJ). Foi vereador do Rio desde 2000 e renunciou em dez/2025. Eleito senador por Santa Catarina em 2026 pelo PL, com 2.041.840 votos (dados do TSE reproduzidos pelo HubPolítico). Citado no relatório da PF de 2022 sobre o "gabinete do ódio"; teve sigilo bancário quebrado (2021) em apuração de rachadinha; alvo de busca em jan/2024 na investigação da Abin paralela. Sócio da Bravo Grafeno. | E12: Santa Catarina (SC), senador eleito; antes, vereador no Rio (RJ) | F12: Vivo | G12: Sem condenação nas fontes que li. Depoimento de porteiro que o ligava ao caso Marielle foi retratado, sem acusação formal a ele. | H12: Investigado / alvo (sem denúncia) | I12: Sem acusação de milícia. | J12: Eleição baseada em página que reproduz dados do TSE; não achei a matéria de apuração. | K12: Wikipedia https://pt.wikipedia.org/wiki/Carlos_Bolsonaro | HubPolítico https://hubpolitico.com.br/perfil/carlosbolsonaro2/informacoes | Condecorações a 16 policiais denunciados (noticias.uol.com.br) https://noticias.uol.com.br/colunas/juliana-dal-piva/2022/09/23/cla-bolsonaro-condecorou-16-pms-denunciados-em-organizacoes-criminosas.htm?cmpid=copiaecola | L12: 20/10/2026 | M12: Eleito senador por SC; deixou a Câmara de Vereadores. 21/10/2026: importado do acervo a verdade. (bolsomaster.site). | N12: carlos.jpg | O12: Wikimedia Commons · CC BY 2.0 | P12: https://commons.wikimedia.org/wiki/File:Carlos_Bolsonaro_durante_Encontro_Brasil-Rússia_em_2022.jpg
A13: jair | B13: Jair Messias Bolsonaro | C13: Flávio e família | D13: Nascido em 21/03/1955 (Glicério/Campinas, SP). Ex-capitão do Exército, deputado federal por quase 30 anos e presidente (2019–2022). Inelegível por 8 anos (TSE, jun/2023). Condenado pelo STF por tentativa de golpe: 27 anos e 3 meses. Também investigado no caso das joias. | E13: Brasília (DF) – em prisão domiciliar humanitária (endereço não informado) | F13: Vivo | G13: Preso desde nov/2025; em mar/2026 passou à domiciliar humanitária após broncopneumonia; Moraes decidiu mantê-la em jul/2026. Em 12/10/2026 ainda cumpre em casa, depois de uma cirurgia e da recuperação de pneumonia bacteriana. Está proibido de usar redes sociais, inclusive por terceiros. Moraes liberou as visitas de Flávio (sem fins eleitorais), suspensas desde julho por uma carta publicada em apoio à candidatura. Uma domiciliar anterior caiu depois de ele danificar a tornozeleira. | H13: Condenado | I13: Sem acusação de milícia. | J13: Planilha diz "hoje preso": desde mar/2026 cumpre em casa (domiciliar humanitária). | K13: Tribuna do Sertão 03/07/2026 https://tribunadosertao.com.br/poder-e-governo/2026/07/03/933954-moraes-prorroga-prisao-domiciliar-de-bolsonaro | Congresso em Foco https://www.congressoemfoco.com.br/noticia/119918/defesa-de-bolsonaro-pede-ao-stf-prorrogacao-da-prisao-domiciliar | JB 12/10/2026 https://www.jb.com.br/brasil/justica/2026/10/1061206-moraes-autoriza-flavio-bolsonaro-a-visitar-jair-bolsonaro-em-prisao-domiciliar.html | Agência Brasil jul/2026 https://agenciabrasil.ebc.com.br/justica/noticia/2026-07/alexandre-de-moraes-decide-manter-bolsonaro-em-prisao-domiciliar | O áudio de Bolsonaro e Ramagem sobre Flávio (valor.globo.com) https://valor.globo.com/politica/noticia/2024/07/11/audio-mostra-bolsonaro-e-ramagem-discutindo-como-blindar-flavio-no-caso-das-rachadinhas-segundo-pf.ghtml | A fala de Bolsonaro na reunião ministerial (g1.globo.com) https://g1.globo.com/politica/noticia/2020/05/22/em-reuniao-ministerial-bolsonaro-diz-eu-nao-vou-esperar-foder-a-minha-familia-toda-assista.ghtml | L13: 20/10/2026 | M13: Domiciliar confirmada em 12/10/2026; motivo e visitas de Flávio. 21/10/2026: importado do acervo a verdade. (bolsomaster.site). | N13: jair.jpg | O13: Wikimedia Commons · CC BY 2.0 | P13: https://commons.wikimedia.org/wiki/File:Jair_Bolsonaro_2019_Portrait_(3x4_cropped_center).jpg
A14: wassef | B14: Frederick Wassef | C14: Flávio e família | D14: Nascido em 1965, São Paulo. Advogado criminalista, amigo da família Bolsonaro desde ~2014. Queiroz foi preso em 18/06/2020 numa casa em Atibaia ligada a ele. Alvo de busca em ago/2023 no caso das joias (recompra de um Rolex). A PF o indiciou; em 04/03/2026 a PGR recomendou arquivar o inquérito, e Moraes mandou a PGR analisar o relatório final da PF. Em 30/06/2026 Moraes mandou abrir apuração sigilosa separada a partir de "eventos fortuitos" no celular dele (PGR com 15 dias para opinar). Nega e diz que a busca foi nula. | E14: São Paulo (SP) – não confirmei domicílio atual | F14: Vivo | G14: Indiciado pela PF no inquérito das joias e alvo formal de nova apuração sigilosa. Sem denúncia nem condenação noticiada. | H14: Investigado / alvo (sem denúncia) | I14: Nada nas fontes. Um site cita um advogado que conecta Wassef ao defensor de Queiroz e de Adriano (não verifiquei). | J14: Não confirmei a resposta da PGR após julho. | K14: CartaCapital 19/03/2026 https://www.cartacapital.com.br/justica/moraes-manda-pgr-analisar-dados-de-wassef-no-caso-das-joias-de-bolsonaro/ | NC News 04/07/2026 https://ncnews.com.br/2026/07/04/moraes-manda-abrir-nova-apuracao-sigilosa-sobre-celular-de-wassef/ | Wikipedia en https://en.wikipedia.org/wiki/Frederick_Wassef | L14: 20/10/2026 | M14: Indiciamento confirmado e nova apuração sigilosa (30/06/2026). | N14: wassef.jpg | O14: Agência Senado · CC BY 2.0 | P14: https://commons.wikimedia.org/wiki/File:Frederick_Wassef_(cropped).jpg
A15: queiroz | B15: Fabrício José Carlos de Queiroz | C15: Flávio e família | D15: Ex-subtenente da PM do Rio, ex-assessor de Flávio na Alerj, apontado como operador da rachadinha (relatório do Coaf de 2018: R$ 1,2 mi movimentados). Preso em 18/06/2020 em Atibaia; domiciliar em jul/2020 (tratava câncer); em mar/2021 o STJ revogou a ordem de prisão por excesso de prazo e ele foi solto. A investigação foi anulada (STJ/STF, 2021) e o caso arquivado em 2022. Em 2022 teve ~6,7 mil votos para deputado estadual (não eleito); em 2024, 588 votos para vereador de Saquarema (suplente). Em mar/2026 era subsecretário de Segurança Pública e Ordem Pública de Saquarema e dizia só disputar 2026 com apoio da família Bolsonaro; não há registro de candidatura formalizada em 2026. Em set/2026 se reuniu com Flávio em Brasília. | E15: Saquarema (RJ) | F15: Vivo (ativo em set/2026) | G15: Sem condenação. Hoje sem processo ativo nas fontes que li. | H15: Citado, sem acusação | I15: MP-RJ estimou que Adriano da Nóbrega (chefe do Escritório do Crime, miliciano, morto em fev/2020) transferiu mais de R$ 400 mil a contas ligadas a Queiroz. Queiroz o chama de amigo e ex-colega da PM. Nas fontes ele não é acusado de integrar milícia. | J15: Planilha diz "19 meses sem depor": não consegui verificar. Candidatura em 2026: sem registro de que tenha sido formalizada (conforme a usuária; em mar/2026 ele só cogitava). | K15: Bahia Notícias https://www.bahianoticias.com.br/noticia/249931-miliciano-adriano-da-nobrega-transferiu-r-400-mil-para-fabricio-queiroz | Mais Goiás https://www.maisgoias.com.br/brasil/gilmar-mendes-da-aval-para-soltar-queiroz-apos-stj-revogar-prisao-domiciliar/ | Portal de Prefeitura https://portaldeprefeitura.com.br/bastidores-da-politica/flavio-bolsonaro-pede-votos-para-fabricio-queiroz-pivo-em-suposto/579564/ | Metrópoles 24/03/2026 https://www.metropoles.com/colunas/igor-gadelha/a-condicao-de-queiroz-para-ser-candidato-em-2026 | JB set/2026 https://www.jb.com.br/brasil/politica/2026/09/1060896-flavio-bolsonaro-e-fabricio-queiroz-se-reuniram-em-brasilia-apos-insistencia.html | A acusação de rachadinhas na Alerj (valor.globo.com) https://valor.globo.com/politica/eleicoes-2026/noticia/2026/09/01/flavio-bolsonaro-relembre-o-processo-da-rachadinha.ghtml | A acusação de rachadinhas na Alerj (folhadelondrina.com.br) https://www.folhadelondrina.com.br/ultimas-noticias/entenda-quais-provas-da-rachadinha-contra-flavio-bolsonaro-ainda-valem-3131387e.html | Familiares de Adriano da Nóbrega no gabinete (oglobo.globo.com) https://oglobo.globo.com/politica/flavio-bolsonaro-empregou-mae-mulher-de-chefe-do-escritorio-do-crime-em-seu-gabinete-23391490 | L15: 20/10/2026 | M15: Sem candidatura formalizada em 2026 (confirmado pela usuária); cargo público e encontro com Flávio em set/2026. 21/10/2026: importado do acervo a verdade. (bolsomaster.site).
A16: advflavio | B16: Advogadas de Flávio (2) | C16: Flávio e família | D16: Não pesquisei: não são nomeadas na planilha e são pessoas privadas. | E16: — | F16: — | G16: — | H16: Não pesquisado | I16: — | J16: — | K16: — | L16: 20/10/2026 | M16: —
A17: vorcaro | B17: Daniel Vorcaro | C17: Vorcaro e o Banco Master | D17: Nascido em 06/10/1983, Belo Horizonte. Administrador com MBA no Ibmec; comprou o Banco Máxima em 2018 e o renomeou Master em 2021. Banco liquidado em 18/11/2025 (rombo estimado de R$ 41 bi ao FGC). Família ligada à Igreja Batista da Lagoinha. | E17: Papudinha, Brasília (DF); vinha de Belo Horizonte (MG) | F17: Vivo | G17: Preso em 17/11/2025 em Guarulhos; solto em 28/11 pelo TRF; nova prisão decretada pelo STF em 04/03/2026; está na Papudinha desde 25/06/2026, depois que PF e PGR rejeitaram duas propostas de delação dele. Mendonça é o relator (Toffoli saiu em fev/2026). Em set/2026 mensagens do celular dele atingiram ministros e autoridades, e o plenário do STF ia discutir a validade dessas provas em 15/09; não confirmei o resultado. Em 20/10/2026 a PGR defendeu manter as prisões do pai, de um primo e do cunhado. As fontes não mostram condenação nem denúncia formal. | H17: Preso, sem condenação | I17: Nada nas fontes. | J17: — | K17: Wikipedia en https://en.wikipedia.org/wiki/Daniel_Vorcaro | Times Brasil https://timesbrasil.com.br/brasil/pgr-defende-manutencao-das-prisoes-de-vorcaro-pai-e-investigados-do-caso-master/ | Wikipedia (Banco Master scandal) https://en.wikipedia.org/wiki/Banco_Master_scandal | Mateus Oliver 20/10/2026 https://www.mateusoliverreporter.com.br/2026/10/20/pgr-defende-manutencao-de-prisoes-no-caso-banco-master-e-permanencia-de-fachin-a-frente-de-decisoes-no-stf/ | O acordo de R$ 134 milhões para o filme (intercept.com.br) https://www.intercept.com.br/2026/05/13/audio-flavio-negociou-vorcaro-milhoes/ | Os registros de contato no celular do banqueiro (piaui.uol.com.br) https://piaui.uol.com.br/web/mensagens-celular-flavio-vorcaro/ | A visita após a soltura do banqueiro (metropoles.com) https://www.metropoles.com/colunas/igor-gadelha/flavio-bolsonaro-visitou-vorcaro-em-casa-apos-prisao | A visita na véspera do anúncio da candidatura (metropoles.com) https://www.metropoles.com/colunas/igor-gadelha/flavio-visitou-vorcaro-na-vespera-de-ser-anunciado-presidenciavel | O voo no jato de Vorcaro em janeiro de 2025 (piaui.uol.com.br) https://piaui.uol.com.br/web/flavio-bolsonaro-viajou-em-jato-de-vorcaro/ | A viagem à Flórida e os repasses para o filme (piaui.uol.com.br) https://piaui.uol.com.br/web/feriadao-flavio-vorcaro-florida-dark-horse/ | O aniversário em uma mansão gerida por empresa de Vorcaro (iclnoticias.com.br) https://iclnoticias.com.br/flavio-bolsonaro-aniversario-da-filha-em-mansao/ | L17: 20/10/2026 | M17: Preso na Papudinha desde 25/06/2026; delações rejeitadas; situação das provas no STF. 21/10/2026: importado do acervo a verdade. (bolsomaster.site). | N17: vorcaro.jpg | O17: Márcio Gustavo Vasconcelos · CC0 | P17: https://commons.wikimedia.org/wiki/File:Daniel_Vorcaro_-_2024_(cropped).jpg
A18: zetel | B18: Fabiano Campos Zettel | C18: Vorcaro e o Banco Master | D18: Pastor evangélico, empresário e doador político; lidera a Igreja Batista da Lagoinha (BH); casado com Natália Vorcaro, irmã de Daniel. Para a PF era "operador financeiro" do grupo do Master (contratos usados para justificar transferências, pagamentos ao grupo "A Turma"). | E18: Belo Horizonte (MG) pela igreja; residência não informada | F18: Vivo (preso; confirmado em 20/10/2026) | G18: Preso preventivamente em 04/03/2026 (3ª fase da Operação Compliance Zero; ordem de Mendonça). Em 20/10/2026 a PGR se opôs a revogar a prisão dele, do pai e de um primo de Vorcaro, por falta de mudança nas circunstâncias. Manchetes de jan/2026 dizem que já fora detido ao tentar embarcar para Dubai e solto horas depois. Sem condenação. | H18: Preso, sem condenação | I18: Nada nas fontes. | J18: Não achei a venda do apartamento à WT nas fontes que abri. | K18: Congresso em Foco https://www.congressoemfoco.com.br/noticia/116929/pf-prende-cunhado-de-vorcaro-suspeito-de-operar-esquema-do-master | Mateus Oliver (link na linha do Vorcaro) | Doações de Fabiano Zettel nas eleições de 2022 (cnnbrasil.com.br) https://www.cnnbrasil.com.br/politica/alvo-da-pf-doou-r-5-mi-para-campanhas-de-bolsonaro-e-tarcisio-em-2022/ | O apartamento de Fabiano Zettel e Willer Tomaz (piaui.uol.com.br) https://piaui.uol.com.br/web/flavio-bolsonaro-zettel-tomaz-imovel-vila-nova-conceicao-sao-paulo/ | L18: 20/10/2026 | M18: Segue preso em 20/10/2026 (PGR contra soltura). 21/10/2026: importado do acervo a verdade. (bolsomaster.site). | N18: zetel.jpg | O18: Wikimedia Commons · CC BY-SA 2.0 | P18: https://commons.wikimedia.org/wiki/File:Fabiano_Zettel.jpg
A19: dirjur | B19: Diretor jurídico do Master | C19: Vorcaro e o Banco Master | D19: Não pesquisado: não nomeado na planilha. | E19: — | F19: — | G19: — | H19: Não pesquisado | I19: — | J19: — | K19: — | L19: 20/10/2026 | M19: —
A20: promoter | B20: Promoter | C20: Vorcaro e o Banco Master | D20: Não pesquisado: pessoa privada e não nomeada. | E20: — | F20: — | G20: — | H20: Não pesquisado | I20: — | J20: — | K20: — | L20: 20/10/2026 | M20: —
A21: mordomo | B21: Mordomo do triplex | C21: Vorcaro e o Banco Master | D21: Não pesquisado: pessoa privada e não nomeada. | E21: — | F21: — | G21: — | H21: Não pesquisado | I21: — | J21: — | K21: — | L21: 20/10/2026 | M21: —
A22: mulheres | B22: Mulheres das festas | C22: Vorcaro e o Banco Master | D22: Não pesquisado: pessoas privadas, não nomeadas, incluindo uma de 19 anos. Não faz sentido (nem é seguro) montar perfil. | E22: — | F22: — | G22: — | H22: Não pesquisado | I22: — | J22: — | K22: — | L22: 20/10/2026 | M22: —
A23: eletricista | B23: Eletricista | C23: Flávio e família | D23: Não pesquisado: pessoa privada e não nomeada. | E23: — | F23: — | G23: — | H23: Não pesquisado | I23: — | J23: — | K23: — | L23: 20/10/2026 | M23: —
A24: richarlison | B24: Richarlison | C24: Casas e ativos | D24: Jogador de futebol (seleção brasileira). Via a empresa Sport 70 comprou em 2020 a mansão da Ilha Comprida (Angra dos Reis); diz ter investido ~R$ 10 mi. Em maio/2022 houve reintegração de posse em favor de M Locadora/WT. Em maio/2025 o STJ manteve a decisão favorável à WT de Willer Tomaz. Flávio foi arrolado como testemunha (nega envolvimento). | E24: Atua no futebol; residência não pesquisada | F24: Vivo | G24: Parte lesada na disputa civil; não é investigado. | H24: Citado, sem acusação | I24: Nada nas fontes. | J24: Em jun/2026 uma advogada publicou e retirou um vídeo sobre o caso, retratando-se por imprecisões. Acervo a verdade.: o advogado dele na disputa pela casa foi morto em 2024 no Rio. Nada nas fontes liga Flávio ou Willer ao homicídio. O PDF diz que a mansão é gerida por empresa de Vorcaro; o mapa a registra como da WT. | K24: Poder360 https://www.poder360.com.br/justica/richarlison-briga-na-justica-com-amigo-de-flavio-bolsonaro/ | Congresso em Foco https://www.congressoemfoco.com.br/noticia/120171/disputa-por-mansao-de-r-10-mi-envolve-richarlison-e-flavio-bolsonaro | A disputa pelo imóvel comprado por Richarlison (iclnoticias.com.br) https://iclnoticias.com.br/advogado-defendia-amigo-de-flavio-bolsonaro/ | A disputa pelo imóvel comprado por Richarlison (iclnoticias.com.br) https://iclnoticias.com.br/pf-e-acionada-flavio-bolsonaro-richarlisson/ | A transferência do imóvel disputado em Angra (iclnoticias.com.br) https://iclnoticias.com.br/governo-bolsonaro-imovel-richarlison/ | L24: 20/10/2026 | M24: 21/10/2026: importado do acervo a verdade. (bolsomaster.site). | N24: richarlison.jpg | O24: ALES · CC BY 2.0 | P24: https://commons.wikimedia.org/wiki/File:Richarlison_é_homenageado_na_ALES_(10.July.2019)_12_(cropped2).jpg
A25: dono | B25: Antônio Marcos da Silva | C25: Casas e ativos | D25: Não consegui confirmar o nome nem o papel em fonte pública. As matérias que abri chamam o ex-possuidor apenas de "o então possuidor" e não dizem que ele ouviu Flávio chamar Willer de sócio. Pessoa privada; não aprofundei. | E25: — | F25: — | G25: — | H25: Não pesquisado | I25: — | J25: Afirmação da planilha não confirmada nas minhas fontes. Vale conferir a origem (vídeo do canal Revelando). | K25: — | L25: 20/10/2026 | M25: —
A26: nunes | B26: Kássio Nunes Marques | C26: Poder e Justiça | D26: Ministro do STF, indicado por Jair Bolsonaro em 2020; eleito presidente do TSE em 14/04/2026 para mandato de 2 anos (vice: André Mendonça). PF/Coaf: a Consult Inteligência Tributária recebeu R$ 6,6 mi do Master (ago/2024–jul/2025), valor incompatível com o faturamento declarado; suspeita de triangulação até o filho. Em sessão do STF ele negou ter votado processos do Master e negou que o filho tenha recebido valores. Deputados pediram investigação. | E26: Brasília (DF) | F26: Vivo | G26: Não há processo contra ele nas fontes que li. | H26: Citado, sem acusação | I26: Nada nas fontes. | J26: Acervo a verdade.: o PDF original diz que ele “recebeu R$ 427 mi”. A CNN fala em contrato de advocacia de até R$ 427 mi, condicionado a êxito, o que não comprova recebimento pessoal. Ele nega. | K26: Gazeta do Povo https://www.gazetadopovo.com.br/republica/filho-nunes-marques-teria-recebido-500-mil-master-aponta-pf/ | Times Brasil https://timesbrasil.com.br/brasil/deputados-pedem-investigacao-sobre-nunes-marques-e-master/ | Agência Brasil https://agenciabrasil.ebc.com.br/justica/noticia/2026-04/nunes-marques-e-eleito-presidente-do-tse | O voto de Nunes Marques no caso Alcídia (noticias.uol.com.br) https://noticias.uol.com.br/colunas/a-hora/2026/10/04/kassio-se-declarou-impedido-voltou-atras-e-deu-ganho-bilionario-ao-master.htm | Decisão sobre usinas e mensagens sobre o filho do ministro (noticias.uol.com.br) https://noticias.uol.com.br/colunas/natalia-portinari/2026/09/29/kassio-via-boi-na-linha-em-caso-de-usinas-segundo-mensagens-de-vorcaro.htm?utm_source=chatgpt.com | Contrato de R$ 427 milhões e suspeitas de benefícios (cnnbrasil.com.br) https://www.cnnbrasil.com.br/politica/turma-do-kn-negociou-contrato-de-r-427-mi-com-master-apontam-mensagens/ | Contrato de R$ 427 milhões e suspeitas de benefícios (cnnbrasil.com.br) https://www.cnnbrasil.com.br/politica/dialogos-de-vorcaro-citam-suposta-mesada-de-r-500-mil-para-filho-de-nunes/ | Contrato de R$ 427 milhões e suspeitas de benefícios (almapreta.com.br) https://almapreta.com.br/sessao/politica/apartamento-nunes-marques-prostituta-fabiano-zettel-cunhado-vorcaro/ | Relatos do ex-sócio sobre festas, relógio e lobby (brasildefato.com.br) https://www.brasildefato.com.br/2026/09/29/ex-socio-de-flavio-bolsonaro-cita-festas-com-garotas-de-programa-rolex-de-r-305-mil-e-lobby-com-nunes-marques-diz-site/#google_vignette | L26: 20/10/2026 | M26: Presidente do TSE confirmado (eleito em 14/04/2026). 21/10/2026: importado do acervo a verdade. (bolsomaster.site). | N26: nunes.jpg | O26: Secom/TSE · domínio público | P26: https://commons.wikimedia.org/wiki/File:Nunes_Marques,_February_2025_(cropped).jpg
A27: kevin | B27: Kevin Marques | C27: Poder e Justiça | D27: Advogado, filho de Nunes Marques. Mensagens do celular de Vorcaro sugerem pagamento mensal de R$ 500 mil (planilha enviada por Luiz Rennó em out/2024; reaviso em jul/2025). Ele nega ter prestado serviço ao Master; a defesa diz que recebeu R$ 281,6 mil da Consult por advocacia tributária. | E27: Não informado | F27: Vivo | G27: As fontes não mostram indiciamento nem denúncia. | H27: Citado, sem acusação | I27: Nada nas fontes. | J27: Planilha diz "~R$ 300 mil": as fontes trazem R$ 500 mil/mês (suspeita da PF) e R$ 281,6 mil (versão da defesa). | K27: Gazeta do Povo (link acima) | Decisão sobre usinas e mensagens sobre o filho do ministro (noticias.uol.com.br) https://noticias.uol.com.br/colunas/natalia-portinari/2026/09/29/kassio-via-boi-na-linha-em-caso-de-usinas-segundo-mensagens-de-vorcaro.htm?utm_source=chatgpt.com | Contrato de R$ 427 milhões e suspeitas de benefícios (cnnbrasil.com.br) https://www.cnnbrasil.com.br/politica/turma-do-kn-negociou-contrato-de-r-427-mi-com-master-apontam-mensagens/ | Contrato de R$ 427 milhões e suspeitas de benefícios (cnnbrasil.com.br) https://www.cnnbrasil.com.br/politica/dialogos-de-vorcaro-citam-suposta-mesada-de-r-500-mil-para-filho-de-nunes/ | Contrato de R$ 427 milhões e suspeitas de benefícios (almapreta.com.br) https://almapreta.com.br/sessao/politica/apartamento-nunes-marques-prostituta-fabiano-zettel-cunhado-vorcaro/ | L27: 20/10/2026 | M27: 21/10/2026: importado do acervo a verdade. (bolsomaster.site).
A28: ramagem | B28: Alexandre Ramagem | C28: Poder e Justiça | D28: Nascido em 08/05/1972, Rio de Janeiro. Delegado da PF, diretor-geral da Abin (2019–2022), deputado federal pelo PL (mandato terminou em dez/2025 após a condenação). Condenado pela 1ª Turma do STF em 11/09/2025 (4 a 1) a 16 anos, 1 mês e 15 dias por tentativa de golpe, organização criminosa armada e outros crimes. Prisão preventiva decretada em 21/11/2025. Fugiu via Roraima/Guiana e chegou aos EUA em 11/09/2025. | E28: Estados Unidos (Flórida); em 05/07/2026 estava em Nova Jersey para um jogo do Brasil. Paradeiro atual não informado | F28: Vivo | G28: Foragido da Justiça brasileira. Em 13/04/2026 foi preso pelo ICE em Orlando e solto dois dias depois, sem fiança; o pedido de asilo aguarda análise. Em 05/07/2026 disse à CNN que a extradição "não vai acontecer" e ligou seu retorno ao Brasil às eleições com Flávio candidato. A CNN afirma que um processo de extradição pedido pelo Brasil tramita em paralelo. | H28: Condenado | I28: Nada nas fontes. | J28: Divergência entre fontes resolvida: a CNN (jul/2026) confirma processo de extradição; a Pública (29/09) apenas não menciona. | K28: Agência Pública 29/09/2026 https://apublica.org/2026/09/familia-de-condenado-por-garimpo-na-terra-yanomami-bancou-vida-de-ramagem-nos-eua/ | Wikipedia en https://en.wikipedia.org/wiki/Alexandre_Ramagem | CNN Brasil 05/07/2026 https://www.cnnbrasil.com.br/politica/nos-eua-ramagem-diz-que-extradicao-nao-acontecera-e-cita-volta-ao-brasil/ | O áudio de Bolsonaro e Ramagem sobre Flávio (valor.globo.com) https://valor.globo.com/politica/noticia/2024/07/11/audio-mostra-bolsonaro-e-ramagem-discutindo-como-blindar-flavio-no-caso-das-rachadinhas-segundo-pf.ghtml | L28: 20/10/2026 | M28: Entrevista de 05/07/2026; asilo pendente; processo de extradição em paralelo. 21/10/2026: importado do acervo a verdade. (bolsomaster.site). | N28: ramagem.jpg | O28: Câmara dos Deputados · CC BY 3.0 | P28: https://commons.wikimedia.org/wiki/File:Delegado_Ramagem_(PL_-_RJ)_(cropped).jpg
A29: heleno | B29: Augusto Heleno | C29: Poder e Justiça | D29: General do Exército, ex-ministro-chefe do GSI de Bolsonaro, 78 anos. Condenado a 21 anos em regime fechado (organização criminosa armada e tentativa de golpe). Em 22/12/2025 Moraes concedeu prisão domiciliar humanitária: perícia da PF apontou demência mista (Alzheimer e vascular), em estágio inicial mas de rápida progressão. | E29: Brasília (DF) para atendimento médico; cidade da domiciliar não confirmada | F29: Vivo (confirmado em 16/10/2026) | G29: Condenado a 21 anos; em domiciliar humanitária desde 22/12/2025. Em 14–16/10/2026 Moraes autorizou visitas médicas diárias, uma saída em 22/10 para o Hospital das Forças Armadas e internação urgente sem nova decisão. A perícia da PF aponta demência mista (Alzheimer e vascular), "progressiva e irreversível", além de osteoartrose avançada e risco de queda. | H29: Condenado | I29: Nada nas fontes. | J29: — | K29: Conjur 22/12/2025 https://www.conjur.com.br/2025-dez-22/alexandre-de-moraes-concede-prisao-domiciliar-humanitaria-a-augusto-heleno//?print=1 | Tribuna do Sertão 16/10/2026 https://www.tribunadosertao.com.br/poder-e-governo/2026/10/16/998671-moraes-autoriza-que-heleno-deixe-prisao-domiciliar-para-atendimento-medico-em-brasilia | L29: 20/10/2026 | M29: Saúde e autorizações de Moraes em 14–16/10/2026. | N29: heleno.jpg | O29: Câmara dos Deputados · CC BY 3.0 | P29: https://commons.wikimedia.org/wiki/File:Augusto_Heleno_(cropped).jpg
A30: moro | B30: Sérgio Fernando Moro | C30: Poder e Justiça | D30: Nascido em 01/08/1972, Maringá (PR). Juiz federal por mais de 20 anos (Lava Jato, 13ª Vara de Curitiba); condenou Lula em 2017. Em 2021 o STF reconheceu sua suspeição naquele caso. Ministro da Justiça de Bolsonaro (jan/2019–abr/2020) e senador pelo PR desde 2023. Deixou o Senado para disputar o governo do Paraná pelo PL e foi eleito governador no 1º turno em 04/10/2026. | E30: Curitiba/Paraná (PR), governador eleito | F30: Vivo | G30: Sem condenação criminal nas fontes que li. | H30: Citado, sem acusação | I30: Nada nas fontes. | J30: — | K30: NSC Total https://www.nsctotal.com.br/politica/eleicoes-2026-quem-e-sergio-moro-candidato-do-pl-ao-governo-do-parana | Congresso em Foco https://www.congressoemfoco.com.br/noticia/122688/sergio-moro-e-eleito-governador-do-parana | Tribuna do Sertão 04/10/2026 https://tribunadosertao.com.br/politica/2026/10/04/990712-sergio-moro-e-eleito-governador-do-parana-no-1o-turno | A saída de Moro e a acusação de interferência na PF (g1.globo.com) https://g1.globo.com/politica/noticia/2020/04/24/moro-anuncia-demissao-do-ministerio-da-justica-e-deixa-o-governo-bolsonaro.ghtml | L30: 20/10/2026 | M30: Eleito governador do Paraná no 1º turno (04/10/2026). 21/10/2026: importado do acervo a verdade. (bolsomaster.site). | N30: moro.jpg | O30: Domínio público | P30: https://commons.wikimedia.org/wiki/File:Senador_da_República_Sérgio_Moro.jpg
A31: ciro | B31: Ciro Nogueira | C31: Poder e Justiça | D31: Senador (PP-PI) e presidente nacional do Progressistas. Alvo da 5ª fase da Operação Compliance Zero (maio/2026, ordem de Mendonça): suposta ponte entre Vorcaro e o Congresso, com participação societária avaliada em ~R$ 13 mi comprada por R$ 1 mi e mesada de R$ 300 mil (relatos falam em R$ 500 mil). Proibido de contato com investigados; o irmão deve usar tornozeleira. | E31: Piauí (PI); mandato em Brasília | F31: Vivo | G31: Alvo de operação, sem denúncia. A defesa nega qualquer participação em atividades ilícitas. | H31: Investigado / alvo (sem denúncia) | I31: Nada nas fontes. | J31: Identificação confirmada: o "Círio Nogueira" da transcrição é o senador Ciro Nogueira, investigado no caso Master (busca em 07/05/2026). A aba Notes original ainda diz "inferida". | K31: Correio da Manhã 07/05/2026 https://www.correiodamanha.com.br/politica/2026/05/283952-ciro-nogueira-receberia-mesada-do-master-diz-investigacao.html | Wikipedia (Banco Master scandal) https://en.wikipedia.org/wiki/Banco_Master_scandal | Supostos pagamentos mensais a Ciro Nogueira (agenciabrasil.ebc.com.br) https://agenciabrasil.ebc.com.br/justica/noticia/2026-05/mesada-e-viagens-internacionais-veja-o-que-pf-diz-sobre-ciro-nogueira | Viagens de Ciro e a suspeita de contrapartida política (g1.globo.com) https://g1.globo.com/jornal-nacional/noticia/2026/05/08/pf-suspeita-que-vorcaro-pagou-ao-menos-3-viagens-internacionais-do-senador-ciro-nogueira-do-pp.ghtml | Ciro na Operação Compliance Zero (agenciabrasil.ebc.com.br) https://agenciabrasil.ebc.com.br/justica/noticia/2026-05/policia-federal-deflagra-5a-fase-da-operacao-compliance-zero | Imagens de Ciro e Vorcaro nos Alpes (cnnbrasil.com.br) https://www.cnnbrasil.com.br/blogs/debora-bergamasco/politica/imagens-obtidas-pela-pf-mostram-ciro-nogueira-e-vorcaro-nos-alpes-franceses/ | O custeio da viagem a Courchevel (piaui.uol.com.br) https://piaui.uol.com.br/web/ciro-nogueira-daniel-vorcaro-alpes-franceses-imagens/ | L31: 20/10/2026 | M31: Identificação tratada como confirmada (antes: inferida); busca em 07/05/2026. 21/10/2026: importado do acervo a verdade. (bolsomaster.site). | N31: ciro.jpg | O31: Wikimedia Commons · CC BY-SA 4.0 | P31: https://commons.wikimedia.org/wiki/File:Senador739.jpg
A32: mendonca | B32: André Mendonça | C32: Poder e Justiça | D32: Ministro do STF indicado por Jair Bolsonaro; ex-AGU e ex-ministro da Justiça. Relator do caso Master desde fev/2026, um mês após o instituto que fundou (ITER) receber R$ 5,2 mi de empresa de sócio de Vorcaro. Mensagens mostram o advogado de Vorcaro articulando encontros com ele em fev e mar/2025. Em set/2026 afastou o diretor-geral da PF e revogou a prisão do filho do Careca do INSS. | E32: Brasília (DF) | F32: Vivo | G32: Não há processo contra ele nas fontes do acervo. | H32: Citado, sem acusação | I32: Nada nas fontes. | J32: Dados do acervo a verdade.; fontes não reverificadas uma a uma. Os levantamentos de contratos do ITER (52 contratos e R$ 8,2 mi; 55 contratos e R$ 10,8 mi) são recortes diferentes e não se somam. | K32: A visita à alfaiataria com o advogado de Vorcaro (iclnoticias.com.br) https://iclnoticias.com.br/vaza-mendonca-mensagens-e-audios-ineditos/ | Encomendas, recibos e pagamentos na alfaiataria (oglobo.globo.com) https://oglobo.globo.com/politica/noticia/2026/09/03/alfaiataria-visitada-por-mendonca-e-advogado-de-vorcaro-nao-esclarece-encomenda-nem-mostra-recibos-ternos-sob-medida-custam-a-partir-de-r-219-mil.ghtml | Encomendas, recibos e pagamentos na alfaiataria (paulomotoryn.substack.com) https://paulomotoryn.substack.com/p/exclusivo-vorcaro-gastou-r-500-mil | Encomendas, recibos e pagamentos na alfaiataria (metro1.com.br) https://www.metro1.com.br/noticias/politica/187938,notas-de-mendonca-em-alfaiataria-frequentada-por-vorcaro-registravam-sem-pagamento | Mensagens para agendar encontro com Mendonça (iclnoticias.com.br) https://iclnoticias.com.br/vaza-mendonca-mensagens-e-audios-ineditos/ | O convite a Bruno Bianco para a reunião (iclnoticias.com.br) https://iclnoticias.com.br/vaza-mendonca-mensagens-e-audios-ineditos/ | A reunião de fevereiro de 2025 (iclnoticias.com.br) https://iclnoticias.com.br/vaza-mendonca-mensagens-e-audios-ineditos/ | Encontro com Vorcaro na sede do ITER (iclnoticias.com.br) https://iclnoticias.com.br/vaza-mendonca-mensagens-e-audios-ineditos/ | Pedido de vista no julgamento sobre cemitérios (valor.globo.com) https://valor.globo.com/politica/noticia/2026/09/15/stf-em-ao-sobre-cemitrios-em-sp-dino-pede-nova-investigao-de-mendona.ghtml | Convites para coquetéis do instituto (iclnoticias.com.br) https://iclnoticias.com.br/vorcaro-foi-chamado-a-coquetel-de-mendonca/ | A viagem de helicóptero de Mendonça (noticias.uol.com.br) https://noticias.uol.com.br/colunas/daniela-lima/2026/09/22/mendonca-voou-em-aeronave-de-ex-parceiro-de-negocios-de-vorcaro.htm | Aporte de R$ 5,2 milhões ao ITER (noticias.uol.com.br) https://noticias.uol.com.br/ultimas-noticias/redacao/2026/09/17/ex-parceiro-de-vorcaro-pos-r-5-milhoes-em-instituto-de-mendonca.htm | Depoimento de Vorcaro sem a Polícia Federal (iclnoticias.com.br) https://iclnoticias.com.br/gabinete-mendonca-ouviu-vorcaro-horario-pf/ | O afastamento de um diretor da PF (cnnbrasil.com.br) https://www.cnnbrasil.com.br/blogs/teo-cury/politica/mendonca-ordenou-afastamento-de-diretor-geral-da-pf-sem-ouvir-pgr/ | A atuação do diretor afastado nos casos Master e INSS (iclnoticias.com.br) https://iclnoticias.com.br/diretor-da-pf-afastado-mendonca-prendeu-vorcaro/ | Revogação da prisão do filho do Careca do INSS (iclnoticias.com.br) https://iclnoticias.com.br/andre-mendonca-revoga-prisao-do-filho-do-careca/ | A contestação da AGU ao afastamento na PF (iclnoticias.com.br) https://iclnoticias.com.br/agu-mendonca-usurpou-competencia-fachin/ | A cronologia entre a operação de Dino e o afastamento (iclnoticias.com.br) https://iclnoticias.com.br/mendonca-cesinha-madureira-vorcaro-dino/ | Financiamento da campanha de Cezinha de Madureira (iclnoticias.com.br) https://iclnoticias.com.br/tarcisio-campanha-deputado-mendonca-vorcaro/ | A proximidade entre Cezinha e Mendonça (iclnoticias.com.br) https://iclnoticias.com.br/cezinha-de-madureira-tinha-porta-retrato-com-mendonca-na-sala-de-casa/ | 52 contratos do ITER com órgãos públicos (apublica.org) https://apublica.org/nota/instituto-de-andre-mendonca-e-alvo-de-representacoes-para-investigar-irregularidades/ | Outro levantamento: 55 contratos do instituto (iclnoticias.com.br) https://iclnoticias.com.br/instituto-de-andre-mendonca-faturou/ | A promoção do irmão de Mendonça (iclnoticias.com.br) https://iclnoticias.com.br/irmao-de-mendonca-foi-promovido-por-nunes/ | Votos relativos a Castro e contratos no Rio (iclnoticias.com.br) https://iclnoticias.com.br/mendonca-votou-a-favor-de-castro-4-vezes/ | Prazos diferentes para decisões sobre políticos (cnnbrasil.com.br) https://www.cnnbrasil.com.br/politica/mendonca-demora-9-dias-para-despachar-sobre-wagner-e-75-sobre-castro/ | O contraste nos prazos apontado pela PF (iclnoticias.com.br) https://iclnoticias.com.br/pf-aponta-diferenca-8-x-no-tempo-mendonca/ | A declaração de Gilmar sobre acesso a dados (iclnoticias.com.br) https://iclnoticias.com.br/gilmar-stf-dados-maste-ministros-mendonca/ | O pedido para rastrear o dinheiro do Master (iclnoticias.com.br) https://iclnoticias.com.br/pf-espera-ha-seis-meses-decisao-mendonca/ | A recomendação de sigilo sobre o celular de Vorcaro (iclnoticias.com.br) https://iclnoticias.com.br/contra-transparencia-mendonca-recomenda-manter/ | Tratamento de ministros em relatório da PF (iclnoticias.com.br) https://iclnoticias.com.br/relatorio-pf-mendonca-poupou-toffoli-kassio/ | O pedido de nulidade apresentado por Gonet (iclnoticias.com.br) https://iclnoticias.com.br/gonet-diz-que-mendonca-investigou-moraes/ | L32: 21/10/2026 | M32: 21/10/2026: importado do acervo a verdade. (bolsomaster.site) (perfil novo).
A33: faria | B33: Fábio Faria | C33: Vorcaro e o Banco Master | D33: Ex-ministro das Comunicações de Jair Bolsonaro. Mensagens recuperadas pela PF o apontam como intermediário de Vorcaro com autoridades em Brasília e com ministros de tribunais superiores, inclusive na organização de festas. Empresa ligada a Vorcaro pagou R$ 67,5 mi por um projeto dele. | E33: Brasília (DF) | F33: Vivo | G33: O acervo não informa se ele é formalmente investigado. | H33: Citado, sem acusação | I33: Nada nas fontes. | J33: Dados do acervo a verdade.; fontes não reverificadas uma a uma. | K33: Fábio Faria como interlocutor de Vorcaro (piaui.uol.com.br) https://piaui.uol.com.br/web/fabio-faria-daniel-vorcaro-lobby/ | R$ 67,5 milhões por projeto de Fábio Faria (tab.uol.com.br) https://tab.uol.com.br/noticias/redacao/2026/01/29/vorcaro-pagou-r-675-mi-em-projeto-eolico-de-fabio-faria-ex-ministro.htm | Convites a autoridades para festas e encontros (piaui.uol.com.br) https://piaui.uol.com.br/web/festa-suicas-vorcaro-fabio-faria/ | O grupo com Hugo Motta, Ciro e Fábio Faria (gazetadopovo.com.br) https://www.gazetadopovo.com.br/republica/vorcaro-grupo-motta-ciro-nogueira-fabio-faria-organizar-encontros/ | A intermediação de contatos com Moraes (g1.globo.com) https://g1.globo.com/politica/noticia/2026/09/01/ex-ministro-fabio-faria-atuou-para-intermediar-contatos-entre-vorcaro-e-moraes-aponta-pf.ghtml | L33: 21/10/2026 | M33: 21/10/2026: importado do acervo a verdade. (bolsomaster.site) (perfil novo).
A34: frias | B34: Mario Frias | C34: Flávio e família | D34: Ex-secretário especial de Cultura de Jair Bolsonaro e produtor-executivo do filme Dark Horse. Áudio divulgado pelo Intercept mostra ele agradecendo Vorcaro pelo financiamento do filme. | E34: — | F34: Vivo | G34: Segundo o PDF, investigado no caso do filme. | H34: Investigado / alvo (sem denúncia) | I34: Nada nas fontes. | J34: Situação de investigado vem do PDF do acervo; não reverificada. | K34: Mario Frias e a produção de Dark Horse (intercept.com.br) https://www.intercept.com.br/2026/05/19/audio-mario-frias-daniel-vorcaro/ | L34: 21/10/2026 | M34: 21/10/2026: importado do acervo a verdade. (bolsomaster.site) (perfil novo).
A35: gaspar | B35: Alfredo Gaspar | C35: Flávio e família | D35: Vice na chapa de Flávio Bolsonaro em 2026. | E35: Alagoas (AL) | F35: Vivo | G35: Pedido de investigação por estupro de vulnerável arquivado pelo ministro Gilmar Mendes em out/2026, por falta de indícios suficientes. Ele nega. | H35: Citado, sem acusação | I35: Nada nas fontes. | J35: O PDF original diz que ele “é investigado”; isso está desatualizado desde o arquivamento (Folha e UOL, 06/10/2026). | K35: Alfredo Gaspar: pedido de investigação arquivado (metropoles.com) https://www.metropoles.com/colunas/igor-gadelha/denuncia-de-suposto-estupro-contra-vice-de-flavio-deve-avancar-no-stf | Alfredo Gaspar: pedido de investigação arquivado (folha.uol.com.br) https://www1.folha.uol.com.br/poder/2026/10/gilmar-arquiva-pedido-de-investigacao-contra-vice-de-flavio-bolsonaro-por-suspeita-de-estupro.shtml | Alfredo Gaspar: pedido de investigação arquivado (noticias.uol.com.br) https://noticias.uol.com.br/eleicoes/2026/10/06/gilmar-mendes-arquiva-stf-suspeita-estupro-alfredo-gaspar-vice-flavio.ghtm | L35: 21/10/2026 | M35: 21/10/2026: importado do acervo a verdade. (bolsomaster.site) (perfil novo).

Sheet Nodes
A1: Id | B1: Label | C1: Type | D1: Group | E1: Description | F1: Degree | G1: Foto (arquivo) | H1: Crédito da foto | I1: Link da fonte da foto | J1: Nota da foto (opcional)
A2: assoc | B2: Associações de aposentados | C2: Instituição ou caso | D2: Esquema do INSS | E2: Descontos sem autorização: mais de R$ 6 bi em 5 anos | F2: =COUNTIF(Edges!$A$2:$A$182,A2)+COUNTIF(Edges!$B$2:$B$182,A2)
A3: careca | B3: Careca do INSS | C3: Pessoa | D3: Esquema do INSS | E3: Lobista Antônio C. Camilo Antunes; preso; apontado pela PF como centro do esquema | F3: =COUNTIF(Edges!$A$2:$A$182,A3)+COUNTIF(Edges!$B$2:$B$182,A3)
A4: contador | B4: Alexandre Caetano dos Reis | C4: Pessoa | D4: Esquema do INSS | E4: Contador do Careca e do escritório de Flávio; preso | F4: =COUNTIF(Edges!$A$2:$A$182,A4)+COUNTIF(Edges!$B$2:$B$182,A4)
A5: leticia | B5: Letícia Caetano dos Reis | C5: Pessoa | D5: Esquema do INSS | E5: Irmã do contador; administra o escritório de Flávio | F5: =COUNTIF(Edges!$A$2:$A$182,A5)+COUNTIF(Edges!$B$2:$B$182,A5)
A6: lulinha | B6: Lulinha | C6: Pessoa | D6: Esquema do INSS | E6: 3 inquéritos no STF; nega; sem indiciamento | F6: =COUNTIF(Edges!$A$2:$A$182,A6)+COUNTIF(Edges!$B$2:$B$182,A6)
A7: roberta | B7: Roberta (lobista) | C7: Pessoa | D7: Esquema do INSS | E7: Amiga de Lulinha; recebeu ~R$ 1 mi de empresa de fachada do Careca | F7: =COUNTIF(Edges!$A$2:$A$182,A7)+COUNTIF(Edges!$B$2:$B$182,A7)
A8: sala | B8: Sala em Águas Claras (DF) | C8: Casa ou ativo | D8: Esquema do INSS | E8: Endereço de Bravo Grafeno e de 16 empresas do Careca | F8: =COUNTIF(Edges!$A$2:$A$182,A8)+COUNTIF(Edges!$B$2:$B$182,A8)
A9: bravo | B9: Bravo Grafeno | C9: Empresa | D9: Esquema do INSS | E9: Fábrica de capacetes de Flávio e Carlos | F9: =COUNTIF(Edges!$A$2:$A$182,A9)+COUNTIF(Edges!$B$2:$B$182,A9)
